Workbook
Name _ftn1: Титульный!$D$52
Name _ftn2: Титульный!$D$53
Name _ftnref1: Титульный!$D$21
Name _ftnref2: Титульный!$D$26
Name x: '2.6 Метод целевой фн Вар11 1'!$B$11
Name y: '2.6 Метод целевой фн Вар11 1'!$B$12

Sheet Титульный

Sheet 1.1 - 1.2 Вариант 8
A1: Статьи дохода | B1: Доход в 2012 г. (отчет) | D1: Доход в 2013 г. (план) | F1: Превышение доходов
B2: Сумма, тыс. руб | C2: Удельный вес, % | D2: Сумма, тыс. руб | E2: Удельный вес, % | F2: Сумма, тыс. руб | G2: В % к 2012 г.
A3: Налоговые доходы | B3: =SUM(B4:B9) -> 1403660 | C3: =(100*B3)/$B$14 -> 98.340281 | D3: =SUM(D4:D9) -> 1609074 | E3: =(100*D3)/$D$14 -> 97.252046 | F3: =D3-B3 -> 205414 | G3: =(100*F3)/$F$14 -> 90.415071
A4: 1. Налоги на прибыль (доход), прирост капитала | B4: 347660 | C4: =(100*B4)/$B$14 -> 24.357025 | D4: 666562 | E4: =(100*D4)/$D$14 -> 40.286847 | F4: =D4-B4 -> 318902 | G4: =(100*F4)/$F$14 -> 140.36797
A5: 2. Налоги на товары и услуги, лицензионные сборы | B5: 396110 | C5: =(100*B5)/$B$14 -> 27.751427 | D5: 142887 | E5: =(100*D5)/$D$14 -> 8.6360559 | F5: =D5-B5 -> -253223 | G5: =(100*F5)/$F$14 -> -111.45869
A6: 3. Налоги на совокупный доход | B6: 53810 | C6: =(100*B6)/$B$14 -> 3.7699233 | D6: 35696 | E6: =(100*D6)/$D$14 -> 2.1574577 | F6: =D6-B6 -> -18114 | G6: =(100*F6)/$F$14 -> -7.9730622
A7: 4. Налоги на имущество | B7: 266900 | C7: =(100*B7)/$B$14 -> 18.698988 | D7: 107253 | E7: =(100*D7)/$D$14 -> 6.4823455 | F7: =D7-B7 -> -159647 | G7: =(100*F7)/$F$14 -> -70.270258
A8: 5. Платежи за пользование природными ресурсами | B8: 102600 | C8: =(100*B8)/$B$14 -> 7.1881459 | D8: 382380 | E8: =(100*D8)/$D$14 -> 23.110955 | F8: =D8-B8 -> 279780 | G8: =(100*F8)/$F$14 -> 123.14803
A9: 6. Прочие налоги, пошлины и сборы | B9: 236580 | C9: =(100*B9)/$B$14 -> 16.574771 | D9: 274296 | E9: =(100*D9)/$D$14 -> 16.578384 | F9: =D9-B9 -> 37716 | G9: =(100*F9)/$F$14 -> 16.601083
A10: Неналоговые доходы | B10: =SUM(B11:B13) -> 23690 | C10: =(100*B10)/$B$14 -> 1.6597191 | D10: =SUM(D11:D13) -> 45466 | E10: =(100*D10)/$D$14 -> 2.7479541 | F10: =D10-B10 -> 21776 | G10: =(100*F10)/$F$14 -> 9.5849289
A11: 1. Доходы от имущества, находящегося в госсобственности | B11: 10690 | C11: =(100*B11)/$B$14 -> 0.74894034 | D11: 37366 | E11: =(100*D11)/$D$14 -> 2.2583921 | F11: =D11-B11 -> 26676 | G11: =(100*F11)/$F$14 -> 11.741714
A12: 2. Административные платежи и сборы | B12: 9500 | C12: =(100*B12)/$B$14 -> 0.66556906 | D12: 4500 | E12: =(100*D12)/$D$14 -> 0.27197892 | F12: =D12-B12 -> -5000 | G12: =(100*F12)/$F$14 -> -2.2008011
A13: 3. Штрафные санкции | B13: 3500 | C13: =(100*B13)/$B$14 -> 0.24520965 | D13: 3600 | E13: =(100*D13)/$D$14 -> 0.21758313 | F13: =D13-B13 -> 100 | G13: =(100*F13)/$F$14 -> 0.044016022
A14: Итого доходов | B14: =SUM(B3,B10) -> 1427350 | C14: =(100*B14)/$B$14 -> 100 | D14: =D10+D3 -> 1654540 | E14: =(100*D14)/$D$14 -> 100 | F14: =D14-B14 -> 227190 | G14: =(100*F14)/$F$14 -> 100

Sheet 1.3 Построение графиков Вар 11
A1: Ось X | B1: Ось Y
A2: Шаг 0,5
A3: =-2 -> -2 | B3: =IF(A3<=-1,((1+ABS(A3))/(1+A3+A3^2)/(1/3)),(((1-COS(2*A3))/2)*(SQRT(1+A3)))) -> 3
A4: =A3+0.5 -> -1.5 | B4: =IF(A4<=-1,((1+ABS(A4))/(1+A4+A4^2)/(1/3)),(((1-COS(2*A4))/2)*(SQRT(1+A4)))) -> 4.2857143
A5: =A4+0.5 -> -1 | B5: =IF(A5<=-1,((1+ABS(A5))/(1+A5+A5^2)/(1/3)),(((1-COS(2*A5))/2)*(SQRT(1+A5)))) -> 6
A6: =A5+0.5 -> -0.5 | B6: =IF(A6<=-1,((1+ABS(A6))/(1+A6+A6^2)/(1/3)),(((1-COS(2*A6))/2)*(SQRT(1+A6)))) -> 0.16252768
A7: =A6+0.5 -> 0 | B7: =IF(A7<=-1,((1+ABS(A7))/(1+A7+A7^2)/(1/3)),(((1-COS(2*A7))/2)*(SQRT(1+A7)))) -> 0
A8: =A7+0.5 -> 0.5 | B8: =IF(A8<=-1,((1+ABS(A8))/(1+A8+A8^2)/(1/3)),(((1-COS(2*A8))/2)*(SQRT(1+A8)))) -> 0.2815062
A9: =A8+0.5 -> 1 | B9: =IF(A9<=-1,((1+ABS(A9))/(1+A9+A9^2)/(1/3)),(((1-COS(2*A9))/2)*(SQRT(1+A9)))) -> 1.001367
A10: =A9+0.5 -> 1.5 | B10: =IF(A10<=-1,((1+ABS(A10))/(1+A10+A10^2)/(1/3)),(((1-COS(2*A10))/2)*(SQRT(1+A10)))) -> 1.5732272
A11: =A10+0.5 -> 2 | B11: =IF(A11<=-1,((1+ABS(A11))/(1+A11+A11^2)/(1/3)),(((1-COS(2*A11))/2)*(SQRT(1+A11)))) -> 1.4320974
A12: Шаг 0,2
A13: =-2 -> -2 | B13: =IF(A13<=-1,((1+ABS(A13))/(1+A13+A13^2)/(1/3)),(((1-COS(2*A13))/2)*(SQRT(1+A13)))) -> 3
A14: =A13+0.2 -> -1.8 | B14: =IF(A14<=-1,((1+ABS(A14))/(1+A14+A14^2)/(1/3)),(((1-COS(2*A14))/2)*(SQRT(1+A14)))) -> 3.442623
A15: =A14+0.2 -> -1.6 | B15: =IF(A15<=-1,((1+ABS(A15))/(1+A15+A15^2)/(1/3)),(((1-COS(2*A15))/2)*(SQRT(1+A15)))) -> 3.9795918
A16: =A15+0.2 -> -1.4 | B16: =IF(A16<=-1,((1+ABS(A16))/(1+A16+A16^2)/(1/3)),(((1-COS(2*A16))/2)*(SQRT(1+A16)))) -> 4.6153846
A17: =A16+0.2 -> -1.2 | B17: =IF(A17<=-1,((1+ABS(A17))/(1+A17+A17^2)/(1/3)),(((1-COS(2*A17))/2)*(SQRT(1+A17)))) -> 5.3225806
A18: =A17+0.2 -> -1 | B18: =IF(A18<=-1,((1+ABS(A18))/(1+A18+A18^2)/(1/3)),(((1-COS(2*A18))/2)*(SQRT(1+A18)))) -> 6
A19: =A18+0.2 -> -0.8 | B19: =IF(A19<=-1,((1+ABS(A19))/(1+A19+A19^2)/(1/3)),(((1-COS(2*A19))/2)*(SQRT(1+A19)))) -> 0.23013601
A20: =A19+0.2 -> -0.6 | B20: =IF(A20<=-1,((1+ABS(A20))/(1+A20+A20^2)/(1/3)),(((1-COS(2*A20))/2)*(SQRT(1+A20)))) -> 0.20164018
A21: =A20+0.2 -> -0.4 | B21: =IF(A21<=-1,((1+ABS(A21))/(1+A21+A21^2)/(1/3)),(((1-COS(2*A21))/2)*(SQRT(1+A21)))) -> 0.11746499
A22: =A21+0.2 -> -0.2 | B22: =IF(A22<=-1,((1+ABS(A22))/(1+A22+A22^2)/(1/3)),(((1-COS(2*A22))/2)*(SQRT(1+A22)))) -> 0.035302597
A23: =A22+0.2 -> -2.7755576e-16 | B23: =IF(A23<=-1,((1+ABS(A23))/(1+A23+A23^2)/(1/3)),(((1-COS(2*A23))/2)*(SQRT(1+A23)))) -> 0
A24: =A23+0.2 -> 0.2 | B24: =IF(A24<=-1,((1+ABS(A24))/(1+A24+A24^2)/(1/3)),(((1-COS(2*A24))/2)*(SQRT(1+A24)))) -> 0.043236674
A25: =A24+0.2 -> 0.4 | B25: =IF(A25<=-1,((1+ABS(A25))/(1+A25+A25^2)/(1/3)),(((1-COS(2*A25))/2)*(SQRT(1+A25)))) -> 0.17943073
... A33: =A32+0.2 -> 2 | B33: =IF(A33<=-1,((1+ABS(A33))/(1+A33+A33^2)/(1/3)),(((1-COS(2*A33))/2)*(SQRT(1+A33)))) -> 1.4320974
A34: Шаг 0,1
A35: =-2 -> -2 | B35: =IF(A35<=-1,((1+ABS(A35))/(1+A35+A35^2)/(1/3)),(((1-COS(2*A35))/2)*(SQRT(1+A35)))) -> 3
A36: =A35+0.1 -> -1.9 | B36: =IF(A36<=-1,((1+ABS(A36))/(1+A36+A36^2)/(1/3)),(((1-COS(2*A36))/2)*(SQRT(1+A36)))) -> 3.2103321
A37: =A36+0.1 -> -1.8 | B37: =IF(A37<=-1,((1+ABS(A37))/(1+A37+A37^2)/(1/3)),(((1-COS(2*A37))/2)*(SQRT(1+A37)))) -> 3.442623
A38: =A37+0.1 -> -1.7 | B38: =IF(A38<=-1,((1+ABS(A38))/(1+A38+A38^2)/(1/3)),(((1-COS(2*A38))/2)*(SQRT(1+A38)))) -> 3.6986301
A39: =A38+0.1 -> -1.6 | B39: =IF(A39<=-1,((1+ABS(A39))/(1+A39+A39^2)/(1/3)),(((1-COS(2*A39))/2)*(SQRT(1+A39)))) -> 3.9795918
A40: =A39+0.1 -> -1.5 | B40: =IF(A40<=-1,((1+ABS(A40))/(1+A40+A40^2)/(1/3)),(((1-COS(2*A40))/2)*(SQRT(1+A40)))) -> 4.2857143
A41: =A40+0.1 -> -1.4 | B41: =IF(A41<=-1,((1+ABS(A41))/(1+A41+A41^2)/(1/3)),(((1-COS(2*A41))/2)*(SQRT(1+A41)))) -> 4.6153846
A42: =A41+0.1 -> -1.3 | B42: =IF(A42<=-1,((1+ABS(A42))/(1+A42+A42^2)/(1/3)),(((1-COS(2*A42))/2)*(SQRT(1+A42)))) -> 4.9640288
A43: =A42+0.1 -> -1.2 | B43: =IF(A43<=-1,((1+ABS(A43))/(1+A43+A43^2)/(1/3)),(((1-COS(2*A43))/2)*(SQRT(1+A43)))) -> 5.3225806
A44: =A43+0.1 -> -1.1 | B44: =IF(A44<=-1,((1+ABS(A44))/(1+A44+A44^2)/(1/3)),(((1-COS(2*A44))/2)*(SQRT(1+A44)))) -> 5.6756757
A45: =A44+0.1 -> -1 | B45: =IF(A45<=-1,((1+ABS(A45))/(1+A45+A45^2)/(1/3)),(((1-COS(2*A45))/2)*(SQRT(1+A45)))) -> 1.9739331e-08
A46: =A45+0.1 -> -0.9 | B46: =IF(A46<=-1,((1+ABS(A46))/(1+A46+A46^2)/(1/3)),(((1-COS(2*A46))/2)*(SQRT(1+A46)))) -> 0.19403769
A47: =A46+0.1 -> -0.8 | B47: =IF(A47<=-1,((1+ABS(A47))/(1+A47+A47^2)/(1/3)),(((1-COS(2*A47))/2)*(SQRT(1+A47)))) -> 0.23013601
...

Sheet 2.1 Корни полинома Вар 11
A4: x | B4: P(x) | D4: значение | E4: |значение| | F4: |А| (start) | G4: |B|(finish) | H4: h | I4: Погрешность | J4: N(кол-во точек) | K4: x1 | L4: x2
A5: -2.6 | B5: =$D$9*(A5^4)+($D$8*(A5^3))+($D$7*(A5^2))+$D$6*A5+$D$5 -> 42.0496 | C5: a0 | D5: -5 | E5: =ABS(D5) -> 5 | F5: =(1/((1+(MAX($E$5:$E$9)))/($E$5))) -> 0.55555556 | G5: =1+(MAX($E$5:$E$9))/$E$5 -> 2.6 | H5: =ABS(($G$5-$F$5)/$J$5) -> 0.20444444 | I5: 1e-05 | J5: 10 | K5: данные из таблицы
A6: =A5+$H$5 -> -2.3955556 | B6: =$D$9*(A6^4)+($D$8*(A6^3))+($D$7*(A6^2))+$D$6*A6+$D$5 -> 32.599987 | C6: a1 | D6: 0 | E6: =ABS(D6) -> 0 | K6: -0.96444444 | L6: 0.67111111
A7: =A6+$H$5 -> -2.1911111 | B7: =$D$9*(A7^4)+($D$8*(A7^3))+($D$7*(A7^2))+$D$6*A7+$D$5 -> 24.898674 | C7: a2 | D7: 8 | E7: =ABS(D7) -> 8
A8: =A7+$H$5 -> -1.9866667 | B8: =$D$9*(A8^4)+($D$8*(A8^3))+($D$7*(A8^2))+$D$6*A8+$D$5 -> 18.629144 | C8: a3 | D8: 3 | E8: =ABS(D8) -> 3
A9: =A8+$H$5 -> -1.7822222 | B9: =$D$9*(A9^4)+($D$8*(A9^3))+($D$7*(A9^2))+$D$6*A9+$D$5 -> 13.516809 | C9: a4 | D9: 1 | E9: =ABS(D9) -> 1
A10: =A9+$H$5 -> -1.5777778 | B10: =$D$9*(A10^4)+($D$8*(A10^3))+($D$7*(A10^2))+$D$6*A10+$D$5 -> 9.3290098
A11: =A10+$H$5 -> -1.3733333 | B11: =$D$9*(A11^4)+($D$8*(A11^3))+($D$7*(A11^2))+$D$6*A11+$D$5 -> 5.8750161
A12: =A11+$H$5 -> -1.1688889 | B12: =$D$9*(A12^4)+($D$8*(A12^3))+($D$7*(A12^2))+$D$6*A12+$D$5 -> 3.0060259
A13: 8 | B13: =$D$9*(A13^4)+($D$8*(A13^3))+($D$7*(A13^2))+$D$6*A13+$D$5 -> 6139
A14: =A13+$H$5 -> 8.2044444 | B14: =$D$9*(A14^4)+($D$8*(A14^3))+($D$7*(A14^2))+$D$6*A14+$D$5 -> 6721.326
A15: =A14+$H$5 -> 8.4088889 | B15: =$D$9*(A15^4)+($D$8*(A15^3))+($D$7*(A15^2))+$D$6*A15+$D$5 -> 7344.2591
A16: =A15+$H$5 -> 8.6133333 | B16: =$D$9*(A16^4)+($D$8*(A16^3))+($D$7*(A16^2))+$D$6*A16+$D$5 -> 8009.6566
A17: =A16+$H$5 -> 8.8177778 | B17: =$D$9*(A17^4)+($D$8*(A17^3))+($D$7*(A17^2))+$D$6*A17+$D$5 -> 8719.418
A18: =A17+$H$5 -> 9.0222222 | B18: =$D$9*(A18^4)+($D$8*(A18^3))+($D$7*(A18^2))+$D$6*A18+$D$5 -> 9475.4844
A19: =A18+$H$5 -> 9.2266667 | B19: =$D$9*(A19^4)+($D$8*(A19^3))+($D$7*(A19^2))+$D$6*A19+$D$5 -> 10279.839
A20: =A19+$H$5 -> 9.4311111 | B20: =$D$9*(A20^4)+($D$8*(A20^3))+($D$7*(A20^2))+$D$6*A20+$D$5 -> 11134.507
A21: 0.68873637 | B21: =$D$9*(A21^4)+($D$8*(A21^3))+($D$7*(A21^2))+$D$6*A21+$D$5 -> -7.8169036e-09
A22: =A21+$H$5 -> 0.89318081 | B22: =$D$9*(A22^4)+($D$8*(A22^3))+($D$7*(A22^2))+$D$6*A22+$D$5 -> 4.1562797
A23: =A22+$H$5 -> 1.0976253 | B23: =$D$9*(A23^4)+($D$8*(A23^3))+($D$7*(A23^2))+$D$6*A23+$D$5 -> 10.056942
A24: =A23+$H$5 -> 1.3020697 | B24: =$D$9*(A24^4)+($D$8*(A24^3))+($D$7*(A24^2))+$D$6*A24+$D$5 -> 18.059946
A25: =A24+$H$5 -> 1.5065141 | B25: =$D$9*(A25^4)+($D$8*(A25^3))+($D$7*(A25^2))+$D$6*A25+$D$5 -> 28.56518
A26: =A25+$H$5 -> 1.7109586 | B26: =$D$9*(A26^4)+($D$8*(A26^3))+($D$7*(A26^2))+$D$6*A26+$D$5 -> 42.014458
A27: =A26+$H$5 -> 1.915403 | B27: =$D$9*(A27^4)+($D$8*(A27^3))+($D$7*(A27^2))+$D$6*A27+$D$5 -> 58.891527
A28: =A27+$H$5 -> 2.1198475 | B28: =$D$9*(A28^4)+($D$8*(A28^3))+($D$7*(A28^2))+$D$6*A28+$D$5 -> 79.722061
A29: =A28+$H$5 -> 2.3242919 | B29: =$D$9*(A29^4)+($D$8*(A29^3))+($D$7*(A29^2))+$D$6*A29+$D$5 -> 105.07366
A30: =A29+$H$5 -> 2.5287364 | B30: =$D$9*(A30^4)+($D$8*(A30^3))+($D$7*(A30^2))+$D$6*A30+$D$5 -> 135.55586

Sheet 2.2 Метод итерации Вар 11
A1: Номер шага | B1: Очередное приближение к корню | C1: Проверка на точность
A2: 0 | B2: =0.25 + SIN(A2) -> 0.25
A3: =A2+1 -> 1 | B3: =0.25 + SIN(B2) -> 0.49740396 | C3: =IF((ABS(B3-B2)<= 0.0001), "STOP", "GO") -> GO
A4: =A3+1 -> 2 | B4: =0.25 + SIN(B3) -> 0.72714569 | C4: =IF((ABS(B4-B3)<= 0.0001), "STOP", "GO") -> GO
A5: =A4+1 -> 3 | B5: =0.25 + SIN(B4) -> 0.91473996 | C5: =IF((ABS(B5-B4)<= 0.0001), "STOP", "GO") -> GO
A6: =A5+1 -> 4 | B6: =0.25 + SIN(B5) -> 1.042404 | C6: =IF((ABS(B6-B5)<= 0.0001), "STOP", "GO") -> GO
A7: =A6+1 -> 5 | B7: =0.25 + SIN(B6) -> 1.1136187 | C7: =IF((ABS(B7-B6)<= 0.0001), "STOP", "GO") -> GO
A8: =A7+1 -> 6 | B8: =0.25 + SIN(B7) -> 1.1473019 | C8: =IF((ABS(B8-B7)<= 0.0001), "STOP", "GO") -> GO
A9: =A8+1 -> 7 | B9: =0.25 + SIN(B8) -> 1.1616585 | C9: =IF((ABS(B9-B8)<= 0.0001), "STOP", "GO") -> GO
A10: =A9+1 -> 8 | B10: =0.25 + SIN(B9) -> 1.1674641 | C10: =IF((ABS(B10-B9)<= 0.0001), "STOP", "GO") -> GO
A11: =A10+1 -> 9 | B11: =0.25 + SIN(B10) -> 1.1697583 | C11: =IF((ABS(B11-B10)<= 0.0001), "STOP", "GO") -> GO
A12: =A11+1 -> 10 | B12: =0.25 + SIN(B11) -> 1.1706563 | C12: =IF((ABS(B12-B11)<= 0.0001), "STOP", "GO") -> GO
A13: =A12+1 -> 11 | B13: =0.25 + SIN(B12) -> 1.1710064 | C13: =IF((ABS(B13-B12)<= 0.0001), "STOP", "GO") -> GO
A14: =A13+1 -> 12 | B14: =0.25 + SIN(B13) -> 1.1711428 | C14: =IF((ABS(B14-B13)<= 0.0001), "STOP", "GO") -> GO
... A50: =A49+1 -> 48 | B50: =0.25 + SIN(B49) -> 1.1712297 | C50: =IF((ABS(B50-B49)<= 0.0001), "STOP", "GO") -> STOP

Sheet 2.3 Метод бисекции Вар 1
A1: Граница отрезков локализации | C1: Произведение F(x) на | E1: Середина отрезка | F1: Произведение F(x) для середины отрезка | G1: Проверка на точность
A2: L | B2: R | C2: L границе | D2: R границе
A3: 0 | B3: 2 | C3: =A3-SIN(A3)-0.25 -> -0.25 | D3: =B3-SIN(B3)-0.25 -> 0.84070257 | E3: =(A3+B3)/2 -> 1 | F3: =E3-SIN(E3)-0.25 -> -0.091470985 | G3: =IF((ABS(D3-C3)<= 0.0001), "STOP", "GO") -> GO
A4: =E3 -> 1 | B4: =B3 -> 2 | C4: =A4-SIN(A4)-0.25 -> -0.091470985 | D4: =B4-SIN(B4)-0.25 -> 0.84070257 | E4: =(A4+B4)/2 -> 1.5 | F4: =E4-SIN(E4)-0.25 -> 0.25250501 | G4: =IF((ABS(D4-C4)<= 0.0001), "STOP", "GO") -> GO
A5: =E4 -> 1.5 | B5: =B4 -> 2 | C5: =A5-SIN(A5)-0.25 -> 0.25250501 | D5: =B5-SIN(B5)-0.25 -> 0.84070257 | E5: =(A5+B5)/2 -> 1.75 | F5: =E5-SIN(E5)-0.25 -> 0.51601405 | G5: =IF((ABS(D5-C5)<= 0.0001), "STOP", "GO") -> GO
A6: =E5 -> 1.75 | B6: =B5 -> 2 | C6: =A6-SIN(A6)-0.25 -> 0.51601405 | D6: =B6-SIN(B6)-0.25 -> 0.84070257 | E6: =(A6+B6)/2 -> 1.875 | F6: =E6-SIN(E6)-0.25 -> 0.67091422 | G6: =IF((ABS(D6-C6)<= 0.0001), "STOP", "GO") -> GO
A7: =E6 -> 1.875 | B7: =B6 -> 2 | C7: =A7-SIN(A7)-0.25 -> 0.67091422 | D7: =B7-SIN(B7)-0.25 -> 0.84070257 | E7: =(A7+B7)/2 -> 1.9375 | F7: =E7-SIN(E7)-0.25 -> 0.75398572 | G7: =IF((ABS(D7-C7)<= 0.0001), "STOP", "GO") -> GO
A8: =E7 -> 1.9375 | B8: =B7 -> 2 | C8: =A8-SIN(A8)-0.25 -> 0.75398572 | D8: =B8-SIN(B8)-0.25 -> 0.84070257 | E8: =(A8+B8)/2 -> 1.96875 | F8: =E8-SIN(E8)-0.25 -> 0.79689406 | G8: =IF((ABS(D8-C8)<= 0.0001), "STOP", "GO") -> GO
A9: =E8 -> 1.96875 | B9: =B8 -> 2 | C9: =A9-SIN(A9)-0.25 -> 0.79689406 | D9: =B9-SIN(B9)-0.25 -> 0.84070257 | E9: =(A9+B9)/2 -> 1.984375 | F9: =E9-SIN(E9)-0.25 -> 0.81868654 | G9: =IF((ABS(D9-C9)<= 0.0001), "STOP", "GO") -> GO
A10: =E9 -> 1.984375 | B10: =B9 -> 2 | C10: =A10-SIN(A10)-0.25 -> 0.81868654 | D10: =B10-SIN(B10)-0.25 -> 0.84070257 | E10: =(A10+B10)/2 -> 1.9921875 | F10: =E10-SIN(E10)-0.25 -> 0.82966671 | G10: =IF((ABS(D10-C10)<= 0.0001), "STOP", "GO") -> GO
A11: =E10 -> 1.9921875 | B11: =B10 -> 2 | C11: =A11-SIN(A11)-0.25 -> 0.82966671 | D11: =B11-SIN(B11)-0.25 -> 0.84070257 | E11: =(A11+B11)/2 -> 1.9960938 | F11: =E11-SIN(E11)-0.25 -> 0.83517769 | G11: =IF((ABS(D11-C11)<= 0.0001), "STOP", "GO") -> GO
A12: =E11 -> 1.9960938 | B12: =B11 -> 2 | C12: =A12-SIN(A12)-0.25 -> 0.83517769 | D12: =B12-SIN(B12)-0.25 -> 0.84070257 | E12: =(A12+B12)/2 -> 1.9980469 | F12: =E12-SIN(E12)-0.25 -> 0.8379384 | G12: =IF((ABS(D12-C12)<= 0.0001), "STOP", "GO") -> GO
A13: =E12 -> 1.9980469 | B13: =B12 -> 2 | C13: =A13-SIN(A13)-0.25 -> 0.8379384 | D13: =B13-SIN(B13)-0.25 -> 0.84070257 | E13: =(A13+B13)/2 -> 1.9990234 | F13: =E13-SIN(E13)-0.25 -> 0.83932005 | G13: =IF((ABS(D13-C13)<= 0.0001), "STOP", "GO") -> GO
A14: =E13 -> 1.9990234 | B14: =B13 -> 2 | C14: =A14-SIN(A14)-0.25 -> 0.83932005 | D14: =B14-SIN(B14)-0.25 -> 0.84070257 | E14: =(A14+B14)/2 -> 1.9995117 | F14: =E14-SIN(E14)-0.25 -> 0.8400112 | G14: =IF((ABS(D14-C14)<= 0.0001), "STOP", "GO") -> GO
A15: =E14 -> 1.9995117 | B15: =B14 -> 2 | C15: =A15-SIN(A15)-0.25 -> 0.8400112 | D15: =B15-SIN(B15)-0.25 -> 0.84070257 | E15: =(A15+B15)/2 -> 1.9997559 | F15: =E15-SIN(E15)-0.25 -> 0.84035686 | G15: =IF((ABS(D15-C15)<= 0.0001), "STOP", "GO") -> GO
... A18: =E17 -> 1.999939 | B18: =B17 -> 2 | C18: =A18-SIN(A18)-0.25 -> 0.84061614 | D18: =B18-SIN(B18)-0.25 -> 0.84070257 | E18: =(A18+B18)/2 -> 1.9999695 | F18: =E18-SIN(E18)-0.25 -> 0.84065936 | G18: =IF((ABS(D18-C18)<= 0.0001), "STOP", "GO") -> STOP

Sheet 2.4 Метод обр матр Вар11
B7: x1 | C7: x2 | D7: x3
B8: 7.6 | C8: 5.8 | D8: 4.7 | G8: 10.1
A9: A = | B9: 3.8 | C9: 4.1 | D9: 2.7 | F9: B = | G9: 9.7
B10: 2.9 | C10: 2.1 | D10: 3.8 | G10: 7.8
B15: x1 | C15: x2 | D15: x3
B16: {=MINVERSE(B8:D10)} -> 0.53276706 | C16: -0.6542659 | D16: -0.19407559 | G16: {=MMULT(_xlfn.ANCHORARRAY(B16),G8:G10)} -> -2.4792215
B17: -0.35535724 | C17: 0.8198484 | D17: -0.14300306 | F17: X = | G17: 3.2479974
B18: -0.21020375 | C18: 0.046234073 | D18: 0.49029622 | G18: 2.1497231

Sheet 2.5 Метод Крамера Вар11
B1: 7.6 | C1: 5.8 | D1: 4.7
A2: A = | B2: 3.8 | C2: 4.1 | D2: 2.7
B3: 2.9 | C3: 2.1 | D3: 3.8
A5: Δ= | B5: =MDETERM(B1:D3) -> 18.601
B7: 10.1
A8: B= | B8: 9.7
B9: 7.8
B11: =B7 -> 10.1 | C11: =C1 -> 5.8 | D11: =D1 -> 4.7
A12: Δx1 | B12: =B8 -> 9.7 | C12: =C2 -> 4.1 | D12: =D2 -> 2.7 | E12: = | F12: =MDETERM(B11:D13) -> -46.116 | H12: X1 = Δx1 / Δ | I12: =F12/$B$5 -> -2.4792215
B13: =B9 -> 7.8 | C13: =C3 -> 2.1 | D13: =D3 -> 3.8
B15: =B1 -> 7.6 | C15: =B7 -> 10.1 | D15: =D1 -> 4.7
A16: Δx2 | B16: =B2 -> 3.8 | C16: =B8 -> 9.7 | D16: =D2 -> 2.7 | E16: = | F16: =MDETERM(B15:D17) -> 60.416 | H16: X2 = Δx2 / Δ | I16: =F16/$B$5 -> 3.2479974
B17: =B3 -> 2.9 | C17: =B9 -> 7.8 | D17: =D3 -> 3.8
B19: =B1 -> 7.6 | C19: =C1 -> 5.8 | D19: =B7 -> 10.1
A20: Δx3 | B20: =B2 -> 3.8 | C20: =C2 -> 4.1 | D20: =B8 -> 9.7 | E20: = | F20: =MDETERM(B19:D21) -> 39.987 | H20: X3 = Δx3 / Δ | I20: =F20/$B$5 -> 2.1497231
B21: =B3 -> 2.9 | C21: =C3 -> 2.1 | D21: =B9 -> 7.8

Sheet Отчет о результатах 1
A1: Microsoft Excel 16.78 Отчет о результатах
A2: Лист: [Медведева Лабораторная 1.xlsx]2.6 Метод целевой фн Вар11 1
A3: Отчет создан: 16.08.2024 22:54:29
A4: Результат: Решение найдено. Все ограничения и условия оптимальности выполнены.
A5: Модуль поиска решения
B6: Модуль: Поиск решения нелинейных задач методом ОПГ
B7: Время решения: 4906,846 секунд.
B8: Число итераций: 7 Число подзадач: 0
A9: Параметры поиска решения
B10: Максимальное время Без пределов, Число итераций Без пределов, Precision 0,000001, Использовать автоматическое масштабирование
B11: Сходимость 0,0001, Размер совокупности 100, Случайное начальное значение 0, Правые производные, Обязательные границы
B12: Максимальное число подзадач Без пределов, Максимальное число целочисленных решений Без пределов, Целочисленное отклонение 1%, Считать неотрицательными
A14: Ячейка целевой функции (Значение)
B15: Ячейка | C15: Имя | D15: Исходное значение | E15: Окончательное значение
B16: $A$15 | C16: Левая | D16: 0.10033467 | E16: 8.8934001e-08
A19: Ячейки переменных
B20: Ячейка | C20: Имя | D20: Исходное значение | E20: Окончательное значение | F20: Целочисленное
B21: $B$11 | C21: x | D21: 0 | E21: 0.80658778 | F21: Продолжить
B22: $B$12 | C22: y | D22: 0 | E22: 0.59111435 | F22: Продолжить
A25: Ограничения
B26: Ячейка | C26: Имя | D26: Значение ячейки | E26: Формула | F26: Состояние | G26: Допуск
B27: $A$15 | C27: Левая | D27: 8.8934001e-08 | E27: $A$15=$B$15 | F27: Привязка | G27: 0
B28: $A$16 | C28: Левая | D28: 1 | E28: $A$16=$B$16 | F28: Привязка | G28: 0
B29: $A$15 | C29: Левая | D29: 8.8934001e-08 | E29: $A$15=0 | F29: Привязка | G29: 0

Sheet Отчет об устойчивости 1
A1: Microsoft Excel 16.78 Отчет об устойчивости
A2: Лист: [Медведева Лабораторная 1.xlsx]2.6 Метод целевой фн Вар11 1
A3: Отчет создан: 16.08.2024 22:54:29
A6: Ячейки переменных
D7: Окончательное | E7: Приведенн.
B8: Ячейка | C8: Имя | D8: Значение | E8: Градиент
B9: $B$11 | C9: x | D9: 0.80658778 | E9: 0
B10: $B$12 | C10: y | D10: 0.59111435 | E10: 0
A12: Ограничения
D13: Окончательное | E13: Лагранжа
B14: Ячейка | C14: Имя | D14: Значение | E14: Множитель
B15: $A$15 | C15: Левая | D15: 8.8934001e-08 | E15: 0
B16: $A$16 | C16: Левая | D16: 1 | E16: 0
B17: $A$15 | C17: Левая | D17: 8.8934001e-08 | E17: 0

Sheet Отчет о пределах 1
A1: Microsoft Excel 16.78 Отчет о пределах
A2: Лист: [Медведева Лабораторная 1.xlsx]2.6 Метод целевой фн Вар11 1
A3: Отчет создан: 16.08.2024 22:54:29
C6: Целевая функция
B7: Ячейка | C7: Имя | D7: Значение
B8: $A$15 | C8: Левая | D8: 8.8934001e-08
C11: Переменная | F11: Нижний | G11: Целевая функция | I11: Верхний | J11: Целевая функция
B12: Ячейка | C12: Имя | D12: Значение | F12: Предел | G12: Результат | I12: Предел | J12: Результат
B13: $B$11 | C13: x | D13: 0.80658778 | F13: 0 | G13: 85 | I13: 250 | J13: 18835
B14: $B$12 | C14: y | D14: 0.59111435 | F14: 0 | G14: 110 | I14: 398.5 | J14: 20035

Sheet 2.6 Метод целевой фн Вар11 1
A10: Корни | D10: Формула | E10: Целевая фн
A11: X= | B11: 0.067776395 | D11: =TAN(x*y + 0.1)-x^2 -> 0.095741032 | E11: =D11^2+D12^2 -> 1.0000002
A12: Y= | B12: 0 | D12: =x^2+y^2-1 -> -0.99540636 | E12: 0
A15: Значения X | B15: Значения Y
B16: 0 | C16: =B16+0.5 -> 0.5 | D16: =C16+0.5 -> 1 | E16: =D16+0.5 -> 1.5 | F16: =E16+0.5 -> 2 | G16: =F16+0.5 -> 2.5 | H16: =G16+0.5 -> 3 | I16: =H16+0.5 -> 3.5 | J16: =I16+0.5 -> 4 | ... P16: =O16+0.5 -> 7
A17: 0.067776395 | B17: =TAN($A17*B$16 +0.1) + B$16^2 -> 0.10033467 | C17: =TAN($A17*C$16 +0.1) + C$16^2 -> 0.384694 | D17: =TAN($A17*D$16 +0.1) + D$16^2 -> 1.1693686 | E17: =TAN($A17*E$16 +0.1) + E$16^2 -> 2.4544436 | F17: =TAN($A17*F$16 +0.1) + F$16^2 -> 4.2400083 | G17: =TAN($A17*G$16 +0.1) + G$16^2 -> 6.5261564 | H17: =TAN($A17*H$16 +0.1) + H$16^2 -> 9.3129878 | I17: =TAN($A17*I$16 +0.1) + I$16^2 -> 12.600609 | ... P17: =TAN($A17*P$16 +0.1) + P$16^2 -> 49.647243
A18: =A17+0.001 -> 0.068776395 | B18: =TAN($A18*B$16 +0.1) + B$16^2 -> 0.10033467 | C18: =TAN($A18*C$16 +0.1) + C$16^2 -> 0.38520311 | D18: =TAN($A18*D$16 +0.1) + D$16^2 -> 1.1703974 | E18: =TAN($A18*E$16 +0.1) + E$16^2 -> 2.4560068 | F18: =TAN($A18*F$16 +0.1) + F$16^2 -> 4.2421245 | G18: =TAN($A18*G$16 +0.1) + G$16^2 -> 6.5288489 | H18: =TAN($A18*H$16 +0.1) + H$16^2 -> 9.3162848 | I18: =TAN($A18*I$16 +0.1) + I$16^2 -> 12.604544 | ... P18: =TAN($A18*P$16 +0.1) + P$16^2 -> 49.657221
A19: =A18+0.001 -> 0.069776395 | B19: =TAN($A19*B$16 +0.1) + B$16^2 -> 0.10033467 | C19: =TAN($A19*C$16 +0.1) + C$16^2 -> 0.38571228 | D19: =TAN($A19*D$16 +0.1) + D$16^2 -> 1.1714266 | E19: =TAN($A19*E$16 +0.1) + E$16^2 -> 2.4575709 | F19: =TAN($A19*F$16 +0.1) + F$16^2 -> 4.2442428 | G19: =TAN($A19*G$16 +0.1) + G$16^2 -> 6.5315452 | H19: =TAN($A19*H$16 +0.1) + H$16^2 -> 9.319588 | I19: =TAN($A19*I$16 +0.1) + I$16^2 -> 12.608489 | ... P19: =TAN($A19*P$16 +0.1) + P$16^2 -> 49.667291
A20: =A19+0.001 -> 0.070776395 | B20: =TAN($A20*B$16 +0.1) + B$16^2 -> 0.10033467 | C20: =TAN($A20*C$16 +0.1) + C$16^2 -> 0.38622153 | D20: =TAN($A20*D$16 +0.1) + D$16^2 -> 1.1724562 | E20: =TAN($A20*E$16 +0.1) + E$16^2 -> 2.4591361 | F20: =TAN($A20*F$16 +0.1) + F$16^2 -> 4.2463631 | G20: =TAN($A20*G$16 +0.1) + G$16^2 -> 6.5342453 | H20: =TAN($A20*H$16 +0.1) + H$16^2 -> 9.3228976 | I20: =TAN($A20*I$16 +0.1) + I$16^2 -> 12.612444 | ... P20: =TAN($A20*P$16 +0.1) + P$16^2 -> 49.677456
A21: =A20+0.001 -> 0.071776395 | B21: =TAN($A21*B$16 +0.1) + B$16^2 -> 0.10033467 | C21: =TAN($A21*C$16 +0.1) + C$16^2 -> 0.38673084 | D21: =TAN($A21*D$16 +0.1) + D$16^2 -> 1.1734861 | E21: =TAN($A21*E$16 +0.1) + E$16^2 -> 2.4607022 | F21: =TAN($A21*F$16 +0.1) + F$16^2 -> 4.2484855 | G21: =TAN($A21*G$16 +0.1) + G$16^2 -> 6.5369492 | H21: =TAN($A21*H$16 +0.1) + H$16^2 -> 9.3262136 | I21: =TAN($A21*I$16 +0.1) + I$16^2 -> 12.616409 | ... P21: =TAN($A21*P$16 +0.1) + P$16^2 -> 49.687717
A22: =A21+0.001 -> 0.072776395 | B22: =TAN($A22*B$16 +0.1) + B$16^2 -> 0.10033467 | C22: =TAN($A22*C$16 +0.1) + C$16^2 -> 0.38724022 | D22: =TAN($A22*D$16 +0.1) + D$16^2 -> 1.1745164 | E22: =TAN($A22*E$16 +0.1) + E$16^2 -> 2.4622692 | F22: =TAN($A22*F$16 +0.1) + F$16^2 -> 4.2506101 | G22: =TAN($A22*G$16 +0.1) + G$16^2 -> 6.539657 | H22: =TAN($A22*H$16 +0.1) + H$16^2 -> 9.3295361 | I22: =TAN($A22*I$16 +0.1) + I$16^2 -> 12.620384 | ... P22: =TAN($A22*P$16 +0.1) + P$16^2 -> 49.698078
A23: 1.0677764 | B23: =TAN($A23*B$16 +0.1) + B$16^2 -> 0.10033467 | C23: =TAN($A23*C$16 +0.1) + C$16^2 -> 0.98508689 | D23: =TAN($A23*D$16 +0.1) + D$16^2 -> 3.3454493 | E23: =TAN($A23*E$16 +0.1) + E$16^2 -> -5.3475992 | F23: =TAN($A23*F$16 +0.1) + F$16^2 -> 2.7240905 | G23: =TAN($A23*G$16 +0.1) + G$16^2 -> 5.8596594 | H23: =TAN($A23*H$16 +0.1) + H$16^2 -> 9.1631617 | I23: =TAN($A23*I$16 +0.1) + I$16^2 -> 13.084836 | ... P23: =TAN($A23*P$16 +0.1) + P$16^2 -> 52.483546
A24: =A23+0.001 -> 1.0687764 | B24: =TAN($A24*B$16 +0.1) + B$16^2 -> 0.10033467 | C24: =TAN($A24*C$16 +0.1) + C$16^2 -> 0.98585735 | D24: =TAN($A24*D$16 +0.1) + D$16^2 -> 3.3519657 | E24: =TAN($A24*E$16 +0.1) + E$16^2 -> -5.2605064 | F24: =TAN($A24*F$16 +0.1) + F$16^2 -> 2.7293331 | G24: =TAN($A24*G$16 +0.1) + G$16^2 -> 5.8625375 | H24: =TAN($A24*H$16 +0.1) + H$16^2 -> 9.1662431 | I24: =TAN($A24*I$16 +0.1) + I$16^2 -> 13.090793 | ... P24: =TAN($A24*P$16 +0.1) + P$16^2 -> 52.577792
A25: =A24+0.001 -> 1.0697764 | B25: =TAN($A25*B$16 +0.1) + B$16^2 -> 0.10033467 | C25: =TAN($A25*C$16 +0.1) + C$16^2 -> 0.98662837 | D25: =TAN($A25*D$16 +0.1) + D$16^2 -> 3.3585129 | E25: =TAN($A25*E$16 +0.1) + E$16^2 -> -5.1753541 | F25: =TAN($A25*F$16 +0.1) + F$16^2 -> 2.734549 | G25: =TAN($A25*G$16 +0.1) + G$16^2 -> 5.8654101 | H25: =TAN($A25*H$16 +0.1) + H$16^2 -> 9.1693276 | I25: =TAN($A25*I$16 +0.1) + I$16^2 -> 13.096785 | ... P25: =TAN($A25*P$16 +0.1) + P$16^2 -> 52.676879
A26: =A25+0.001 -> 1.0707764 | B26: =TAN($A26*B$16 +0.1) + B$16^2 -> 0.10033467 | C26: =TAN($A26*C$16 +0.1) + C$16^2 -> 0.98739997 | D26: =TAN($A26*D$16 +0.1) + D$16^2 -> 3.365091 | E26: =TAN($A26*E$16 +0.1) + E$16^2 -> -5.0920778 | F26: =TAN($A26*F$16 +0.1) + F$16^2 -> 2.7397386 | G26: =TAN($A26*G$16 +0.1) + G$16^2 -> 5.8682771 | H26: =TAN($A26*H$16 +0.1) + H$16^2 -> 9.1724152 | I26: =TAN($A26*I$16 +0.1) + I$16^2 -> 13.102813 | ... P26: =TAN($A26*P$16 +0.1) + P$16^2 -> 52.781202
A27: =A26+0.001 -> 1.0717764 | B27: =TAN($A27*B$16 +0.1) + B$16^2 -> 0.10033467 | C27: =TAN($A27*C$16 +0.1) + C$16^2 -> 0.98817213 | D27: =TAN($A27*D$16 +0.1) + D$16^2 -> 3.3717003 | E27: =TAN($A27*E$16 +0.1) + E$16^2 -> -5.0106157 | F27: =TAN($A27*F$16 +0.1) + F$16^2 -> 2.7449021 | G27: =TAN($A27*G$16 +0.1) + G$16^2 -> 5.8711386 | H27: =TAN($A27*H$16 +0.1) + H$16^2 -> 9.1755059 | I27: =TAN($A27*I$16 +0.1) + I$16^2 -> 13.108876 | ... P27: =TAN($A27*P$16 +0.1) + P$16^2 -> 52.891198
A28: =A27+0.001 -> 1.0727764 | B28: =TAN($A28*B$16 +0.1) + B$16^2 -> 0.10033467 | C28: =TAN($A28*C$16 +0.1) + C$16^2 -> 0.98894487 | D28: =TAN($A28*D$16 +0.1) + D$16^2 -> 3.378341 | E28: =TAN($A28*E$16 +0.1) + E$16^2 -> -4.9309089 | F28: =TAN($A28*F$16 +0.1) + F$16^2 -> 2.7500398 | G28: =TAN($A28*G$16 +0.1) + G$16^2 -> 5.8739948 | H28: =TAN($A28*H$16 +0.1) + H$16^2 -> 9.1786 | I28: =TAN($A28*I$16 +0.1) + I$16^2 -> 13.114977 | ... P28: =TAN($A28*P$16 +0.1) + P$16^2 -> 53.007353
A29: 2.0677764 | B29: =TAN($A29*B$16 +0.1) + B$16^2 -> 0.10033467 | C29: =TAN($A29*C$16 +0.1) + C$16^2 -> 2.391287 | D29: =TAN($A29*D$16 +0.1) + D$16^2 -> -0.47121016 | E29: =TAN($A29*E$16 +0.1) + E$16^2 -> 2.3101443 | F29: =TAN($A29*F$16 +0.1) + F$16^2 -> 5.9357482 | G29: =TAN($A29*G$16 +0.1) + G$16^2 -> 4.6444779 | H29: =TAN($A29*H$16 +0.1) + H$16^2 -> 9.0201466 | I29: =TAN($A29*I$16 +0.1) + I$16^2 -> 14.009717 | ... P29: =TAN($A29*P$16 +0.1) + P$16^2 -> 46.86072
A30: =A29+0.001 -> 2.0687764 | B30: =TAN($A30*B$16 +0.1) + B$16^2 -> 0.10033467 | C30: =TAN($A30*C$16 +0.1) + C$16^2 -> 2.3940825 | D30: =TAN($A30*D$16 +0.1) + D$16^2 -> -0.46805034 | E30: =TAN($A30*E$16 +0.1) + E$16^2 -> 2.3116499 | F30: =TAN($A30*F$16 +0.1) + F$16^2 -> 5.9452793 | G30: =TAN($A30*G$16 +0.1) + G$16^2 -> 4.6533864 | H30: =TAN($A30*H$16 +0.1) + H$16^2 -> 9.023148 | I30: =TAN($A30*I$16 +0.1) + I$16^2 -> 14.024144 | ... P30: =TAN($A30*P$16 +0.1) + P$16^2 -> 46.899181
A31: =A30+0.001 -> 2.0697764 | B31: =TAN($A31*B$16 +0.1) + B$16^2 -> 0.10033467 | C31: =TAN($A31*C$16 +0.1) + C$16^2 -> 2.3968841 | D31: =TAN($A31*D$16 +0.1) + D$16^2 -> -0.4648998 | E31: =TAN($A31*E$16 +0.1) + E$16^2 -> 2.3131557 | F31: =TAN($A31*F$16 +0.1) + F$16^2 -> 5.9548849 | G31: =TAN($A31*G$16 +0.1) + G$16^2 -> 4.6622241 | H31: =TAN($A31*H$16 +0.1) + H$16^2 -> 9.0261498 | I31: =TAN($A31*I$16 +0.1) + I$16^2 -> 14.038751 | ... P31: =TAN($A31*P$16 +0.1) + P$16^2 -> 46.936526
A32: =A31+0.001 -> 2.0707764 | B32: =TAN($A32*B$16 +0.1) + B$16^2 -> 0.10033467 | C32: =TAN($A32*C$16 +0.1) + C$16^2 -> 2.3996916 | D32: =TAN($A32*D$16 +0.1) + D$16^2 -> -0.46175847 | E32: =TAN($A32*E$16 +0.1) + E$16^2 -> 2.3146618 | F32: =TAN($A32*F$16 +0.1) + F$16^2 -> 5.9645659 | G32: =TAN($A32*G$16 +0.1) + G$16^2 -> 4.6709919 | H32: =TAN($A32*H$16 +0.1) + H$16^2 -> 9.0291521 | I32: =TAN($A32*I$16 +0.1) + I$16^2 -> 14.053543 | ... P32: =TAN($A32*P$16 +0.1) + P$16^2 -> 46.972808
A33: =A32+0.001 -> 2.0717764 | B33: =TAN($A33*B$16 +0.1) + B$16^2 -> 0.10033467 | C33: =TAN($A33*C$16 +0.1) + C$16^2 -> 2.4025052 | D33: =TAN($A33*D$16 +0.1) + D$16^2 -> -0.4586263 | E33: =TAN($A33*E$16 +0.1) + E$16^2 -> 2.3161683 | F33: =TAN($A33*F$16 +0.1) + F$16^2 -> 5.9743233 | G33: =TAN($A33*G$16 +0.1) + G$16^2 -> 4.6796907 | H33: =TAN($A33*H$16 +0.1) + H$16^2 -> 9.032155 | I33: =TAN($A33*I$16 +0.1) + I$16^2 -> 14.068522 | ... P33: =TAN($A33*P$16 +0.1) + P$16^2 -> 47.008075
A34: =A33+0.001 -> 2.0727764 | B34: =TAN($A34*B$16 +0.1) + B$16^2 -> 0.10033467 | C34: =TAN($A34*C$16 +0.1) + C$16^2 -> 2.4053249 | D34: =TAN($A34*D$16 +0.1) + D$16^2 -> -0.45550327 | E34: =TAN($A34*E$16 +0.1) + E$16^2 -> 2.317675 | F34: =TAN($A34*F$16 +0.1) + F$16^2 -> 5.9841581 | G34: =TAN($A34*G$16 +0.1) + G$16^2 -> 4.6883216 | H34: =TAN($A34*H$16 +0.1) + H$16^2 -> 9.0351584 | I34: =TAN($A34*I$16 +0.1) + I$16^2 -> 14.083693 | ... P34: =TAN($A34*P$16 +0.1) + P$16^2 -> 47.042372
A35: 3.0677764 | B35: =TAN($A35*B$16 +0.1) + B$16^2 -> 0.10033467 | C35: =TAN($A35*C$16 +0.1) + C$16^2 -> -15.578866 | D35: =TAN($A35*D$16 +0.1) + D$16^2 -> 1.0261897 | E35: =TAN($A35*E$16 +0.1) + E$16^2 -> 95.491844 | F35: =TAN($A35*F$16 +0.1) + F$16^2 -> 3.9523314 | G35: =TAN($A35*G$16 +0.1) + G$16^2 -> 18.050436 | H35: =TAN($A35*H$16 +0.1) + H$16^2 -> 8.8779506 | I35: =TAN($A35*I$16 +0.1) + I$16^2 -> 18.511975 | ... P35: =TAN($A35*P$16 +0.1) + P$16^2 -> 48.557363
A36: =A35+0.001 -> 3.0687764 | B36: =TAN($A36*B$16 +0.1) + B$16^2 -> 0.10033467 | C36: =TAN($A36*C$16 +0.1) + C$16^2 -> -15.454077 | D36: =TAN($A36*D$16 +0.1) + D$16^2 -> 1.0271904 | E36: =TAN($A36*E$16 +0.1) + E$16^2 -> 110.65521 | F36: =TAN($A36*F$16 +0.1) + F$16^2 -> 3.9543358 | G36: =TAN($A36*G$16 +0.1) + G$16^2 -> 18.411721 | H36: =TAN($A36*H$16 +0.1) + H$16^2 -> 8.8809941 | I36: =TAN($A36*I$16 +0.1) + I$16^2 -> 18.655873 | ... P36: =TAN($A36*P$16 +0.1) + P$16^2 -> 48.565709
A37: =A36+0.001 -> 3.0697764 | B37: =TAN($A37*B$16 +0.1) + B$16^2 -> 0.10033467 | C37: =TAN($A37*C$16 +0.1) + C$16^2 -> -15.331233 | D37: =TAN($A37*D$16 +0.1) + D$16^2 -> 1.0281912 | E37: =TAN($A37*E$16 +0.1) + E$16^2 -> 131.70753 | F37: =TAN($A37*F$16 +0.1) + F$16^2 -> 3.9563398 | G37: =TAN($A37*G$16 +0.1) + G$16^2 -> 18.795664 | H37: =TAN($A37*H$16 +0.1) + H$16^2 -> 8.8840356 | I37: =TAN($A37*I$16 +0.1) + I$16^2 -> 18.806371 | ... P37: =TAN($A37*P$16 +0.1) + P$16^2 -> 48.574004
A38: =A37+0.001 -> 3.0707764 | B38: =TAN($A38*B$16 +0.1) + B$16^2 -> 0.10033467 | C38: =TAN($A38*C$16 +0.1) + C$16^2 -> -15.210288 | D38: =TAN($A38*D$16 +0.1) + D$16^2 -> 1.029192 | E38: =TAN($A38*E$16 +0.1) + E$16^2 -> 162.9063 | F38: =TAN($A38*F$16 +0.1) + F$16^2 -> 3.9583434 | G38: =TAN($A38*G$16 +0.1) + G$16^2 -> 19.204471 | H38: =TAN($A38*H$16 +0.1) + H$16^2 -> 8.8870749 | I38: =TAN($A38*I$16 +0.1) + I$16^2 -> 18.963938 | ... P38: =TAN($A38*P$16 +0.1) + P$16^2 -> 48.58225
A39: =A38+0.001 -> 3.0717764 | B39: =TAN($A39*B$16 +0.1) + B$16^2 -> 0.10033467 | C39: =TAN($A39*C$16 +0.1) + C$16^2 -> -15.091198 | D39: =TAN($A39*D$16 +0.1) + D$16^2 -> 1.0301929 | E39: =TAN($A39*E$16 +0.1) + E$16^2 -> 213.91608 | F39: =TAN($A39*F$16 +0.1) + F$16^2 -> 3.9603467 | G39: =TAN($A39*G$16 +0.1) + G$16^2 -> 19.640643 | H39: =TAN($A39*H$16 +0.1) + H$16^2 -> 8.8901121 | I39: =TAN($A39*I$16 +0.1) + I$16^2 -> 19.129089 | ... P39: =TAN($A39*P$16 +0.1) + P$16^2 -> 48.590448
A40: =A39+0.001 -> 3.0727764 | B40: =TAN($A40*B$16 +0.1) + B$16^2 -> 0.10033467 | C40: =TAN($A40*C$16 +0.1) + C$16^2 -> -14.973921 | D40: =TAN($A40*D$16 +0.1) + D$16^2 -> 1.0311939 | E40: =TAN($A40*E$16 +0.1) + E$16^2 -> 312.38535 | F40: =TAN($A40*F$16 +0.1) + F$16^2 -> 3.9623497 | G40: =TAN($A40*G$16 +0.1) + G$16^2 -> 20.107031 | H40: =TAN($A40*H$16 +0.1) + H$16^2 -> 8.8931473 | I40: =TAN($A40*I$16 +0.1) + I$16^2 -> 19.302389 | ... P40: =TAN($A40*P$16 +0.1) + P$16^2 -> 48.598599
A41: 4.0677764 | B41: =TAN($A41*B$16 +0.1) + B$16^2 -> 0.10033467 | C41: =TAN($A41*C$16 +0.1) + C$16^2 -> -1.3341205 | D41: =TAN($A41*D$16 +0.1) + D$16^2 -> 2.650936 | E41: =TAN($A41*E$16 +0.1) + E$16^2 -> 2.1682982 | F41: =TAN($A41*F$16 +0.1) + F$16^2 -> 1.5076992 | G41: =TAN($A41*G$16 +0.1) + G$16^2 -> 7.376154 | H41: =TAN($A41*H$16 +0.1) + H$16^2 -> 8.7307191 | I41: =TAN($A41*I$16 +0.1) + I$16^2 -> 7.3181228 | ... P41: =TAN($A41*P$16 +0.1) + P$16^2 -> 49.309447
A42: =A41+0.001 -> 4.0687764 | B42: =TAN($A42*B$16 +0.1) + B$16^2 -> 0.10033467 | C42: =TAN($A42*C$16 +0.1) + C$16^2 -> -1.3323672 | D42: =TAN($A42*D$16 +0.1) + D$16^2 -> 2.6546677 | E42: =TAN($A42*E$16 +0.1) + E$16^2 -> 2.169808 | F42: =TAN($A42*F$16 +0.1) + F$16^2 -> 1.5220508 | G42: =TAN($A42*G$16 +0.1) + G$16^2 -> 7.3818405 | H42: =TAN($A42*H$16 +0.1) + H$16^2 -> 8.7339341 | I42: =TAN($A42*I$16 +0.1) + I$16^2 -> 7.4052511 | ... P42: =TAN($A42*P$16 +0.1) + P$16^2 -> 49.317134
A43: =A42+0.001 -> 4.0697764 | B43: =TAN($A43*B$16 +0.1) + B$16^2 -> 0.10033467 | C43: =TAN($A43*C$16 +0.1) + C$16^2 -> -1.3306167 | D43: =TAN($A43*D$16 +0.1) + D$16^2 -> 2.6584118 | E43: =TAN($A43*E$16 +0.1) + E$16^2 -> 2.1713175 | F43: =TAN($A43*F$16 +0.1) + F$16^2 -> 1.5362608 | G43: =TAN($A43*G$16 +0.1) + G$16^2 -> 7.3875594 | H43: =TAN($A43*H$16 +0.1) + H$16^2 -> 8.7371439 | I43: =TAN($A43*I$16 +0.1) + I$16^2 -> 7.4894739 | ... P43: =TAN($A43*P$16 +0.1) + P$16^2 -> 49.324855
A44: =A43+0.001 -> 4.0707764 | B44: =TAN($A44*B$16 +0.1) + B$16^2 -> 0.10033467 | C44: =TAN($A44*C$16 +0.1) + C$16^2 -> -1.3288689 | D44: =TAN($A44*D$16 +0.1) + D$16^2 -> 2.6621684 | E44: =TAN($A44*E$16 +0.1) + E$16^2 -> 2.1728266 | F44: =TAN($A44*F$16 +0.1) + F$16^2 -> 1.5503315 | G44: =TAN($A44*G$16 +0.1) + G$16^2 -> 7.3933109 | H44: =TAN($A44*H$16 +0.1) + H$16^2 -> 8.7403487 | I44: =TAN($A44*I$16 +0.1) + I$16^2 -> 7.5709361 | ... P44: =TAN($A44*P$16 +0.1) + P$16^2 -> 49.332612

Sheet 3.1 Сортировка
A1: Планета | B1: Период обращения, земной год | C1: Расстояние от Солнца, млн км | D1: Диаметр, тыс.км | E1: Масса, Тт | F1: Количество спутников
A2: Исходная таблица
A3: Меркурий | B3: 0.241 | C3: 58 | D3: 4.9 | E3: =0.32*10^9 -> 320000000 | F3: 0
A4: Венера | B4: 0.615 | C4: 108 | D4: 12.1 | E4: =4.86*10^9 -> 4860000000 | F4: 0
A5: Земля | B5: 1 | C5: 150 | D5: 12.8 | E5: =6*10^9 -> 6000000000 | F5: 1
A6: Марс | B6: 1.881 | C6: 288 | D6: 6.8 | E6: =6.1*10^8 -> 610000000 | F6: 2
A7: Юпитер | B7: 11.86 | C7: 778 | D7: 142.6 | E7: =19.07*10^11 -> 1907000000000 | F7: 16
A8: Сатурн | B8: 29.46 | C8: 1426 | D8: 120.2 | E8: =57.09*10^10 -> 570900000000 | F8: 17
A9: Уран | B9: 84.01 | C9: 2869 | D9: 49 | E9: =87.24*10^9 -> 87240000000 | F9: 14
A10: Нептун | B10: 164.8 | C10: 4496 | D10: 50.2 | E10: =10.34*10^10 -> 103400000000 | F10: 2
A11: Плутон | B11: 247.7 | C11: 5900 | D11: 2.8 | E11: =0.1*10^9 -> 100000000 | F11: 1
A13: Относительная таблица
A14: Меркурий | B14: 0.241 | C14: 0.38666667 | D14: 0.3828125 | E14: 0.053333333 | F14: 0
A15: Венера | B15: 0.615 | C15: 0.72 | D15: 0.9453125 | E15: 0.81 | F15: 0
A16: Земля | B16: 1 | C16: 1 | D16: 1 | E16: 1 | F16: 1
A17: Марс | B17: 1.881 | C17: 1.92 | D17: 0.53125 | E17: 0.10166667 | F17: 2
A18: Юпитер | B18: 11.86 | C18: 5.1866667 | D18: 11.140625 | E18: 317.83333 | F18: 16
A19: Сатурн | B19: 29.46 | C19: 9.5066667 | D19: 9.390625 | E19: 95.15 | F19: 17
A20: Уран | B20: 84.01 | C20: 19.126667 | D20: 3.828125 | E20: 14.54 | F20: 14
A21: Нептун | B21: 164.8 | C21: 29.973333 | D21: 3.921875 | E21: 17.233333 | F21: 2
A22: Плутон | B22: 247.7 | C22: 39.333333 | D22: 0.21875 | E22: 0.016666667 | F22: 1
A24: Таблица с сортировкой данных в порядке убывания количества спутников
A25: Сатурн | B25: 29.46 | C25: 9.5066667 | D25: 9.390625 | E25: 95.15 | F25: 17
A26: Юпитер | B26: 11.86 | C26: 5.1866667 | D26: 11.140625 | E26: 317.83333 | F26: 16
A27: Уран | B27: 84.01 | C27: 19.126667 | D27: 3.828125 | E27: 14.54 | F27: 14
A28: Марс | B28: 1.881 | C28: 1.92 | D28: 0.53125 | E28: 0.10166667 | F28: 2
A29: Нептун | B29: 164.8 | C29: 29.973333 | D29: 3.921875 | E29: 17.233333 | F29: 2
A30: Земля | B30: 1 | C30: 1 | D30: 1 | E30: 1 | F30: 1
A31: Плутон | B31: 247.7 | C31: 39.333333 | D31: 0.29907227 | E31: 0.016666667 | F31: 1
A32: Меркурий | B32: 0.241 | C32: 0.38666667 | D32: 0.3828125 | E32: 0.053333333 | F32: 0
A33: Венера | B33: 0.615 | C33: 0.72 | D33: 0.9453125 | E33: 0.81 | F33: 0
A35: Таблица с сортировкой данных в алфавитном порядке названия планет
A36: Венера | B36: 0.615 | C36: 0.72 | D36: 0.9453125 | E36: 0.81 | F36: 0
A37: Земля | B37: 1 | C37: 1 | D37: 1 | E37: 1 | F37: 1
A38: Марс | B38: 1.881 | C38: 1.92 | D38: 0.53125 | E38: 0.10166667 | F38: 2
A39: Меркурий | B39: 0.241 | C39: 0.38666667 | D39: 0.3828125 | E39: 0.053333333 | F39: 0
A40: Нептун | B40: 164.8 | C40: 29.973333 | D40: 3.921875 | E40: 17.233333 | F40: 2
A41: Плутон | B41: 247.7 | C41: 39.333333 | D41: 0.078125 | E41: 0.016666667 | F41: 1
A42: Сатурн | B42: 29.46 | C42: 9.5066667 | D42: 9.390625 | E42: 95.15 | F42: 17
A43: Уран | B43: 84.01 | C43: 19.126667 | D43: 3.828125 | E43: 14.54 | F43: 14
...

Sheet 3.2 Фильтрация
A1: Планета | B1: Период обращения, земной год | C1: Расстояние от Солнца, млн км | D1: Диаметр, тыс.км | E1: Масса, Тт | F1: Количество спутников
A2: Меркурий | B2: 0.241 | C2: 0.38666667 | D2: 0.3828125 | E2: 0.053333333 | F2: 0
A3: Венера | B3: 0.615 | C3: 0.72 | D3: 0.9453125 | E3: 0.81 | F3: 0
A4: Земля | B4: 1 | C4: 1 | D4: 1 | E4: 1 | F4: 1
A5: Марс | B5: 1.881 | C5: 1.92 | D5: 0.53125 | E5: 0.10166667 | F5: 2
A6: Юпитер | B6: 11.86 | C6: 5.1866667 | D6: 11.140625 | E6: 317.83333 | F6: 16
A7: Сатурн | B7: 29.46 | C7: 9.5066667 | D7: 9.390625 | E7: 95.15 | F7: 17
A8: Уран | B8: 84.01 | C8: 19.126667 | D8: 3.828125 | E8: 14.54 | F8: 14
A9: Нептун | B9: 164.8 | C9: 29.973333 | D9: 3.921875 | E9: 17.233333 | F9: 2
A10: Плутон | B10: 247.7 | C10: 39.333333 | D10: 0.21875 | E10: 0.016666667 | F10: 1

Sheet 3.3.1 Автофильтр
A1: Автофильтр (расширенный без вставки в новую таблицу) для планет с диаметром менее 4х диаметром Земли и периодом обращения более 80 земных лет
A2: Планета | B2: Период обращения, земной год | C2: Диаметр, кол-во земных | D2: Расстояние от Солнца, млн км | E2: Масса, Тт | F2: Количество спутников
B3: >80 | C3: <4
A5: Планета | B5: Период обращения, земной год | C5: Диаметр, кол-во земных | D5: Расстояние от Солнца | E5: Масса, относительно Земли | F5: Количество спутников
A6: Меркурий | B6: 0.241 | C6: 0.38666667 | D6: 0.3828125 | E6: 0.053333333 | F6: 0
A7: Венера | B7: 0.615 | C7: 0.72 | D7: 0.9453125 | E7: 0.81 | F7: 0
A8: Земля | B8: 1 | C8: 1 | D8: 1 | E8: 1 | F8: 1
A9: Марс | B9: 1.881 | C9: 1.92 | D9: 0.53125 | E9: 0.10166667 | F9: 2
A10: Юпитер | B10: 11.86 | C10: 5.1866667 | D10: 11.140625 | E10: 317.83333 | F10: 16
A11: Сатурн | B11: 29.46 | C11: 9.5066667 | D11: 9.390625 | E11: 95.15 | F11: 17
A12: Уран | B12: 84.01 | C12: 19.126667 | D12: 3.828125 | E12: 14.54 | F12: 14
A13: Нептун | B13: 164.8 | C13: 29.973333 | D13: 3.921875 | E13: 17.233333 | F13: 2
A14: Плутон | B14: 247.7 | C14: 39.333333 | D14: 0.21875 | E14: 0.016666667 | F14: 1

Sheet 3.3.2 Автофильтр
A1: Автофильтр (расширенный без вставки в новую таблицу) для планет с расстоянием от Солнца не менее 0,5 от Земли, массой от 1 до 100 масс Земли и не более 2-х спутников
A2: Планета | B2: Период обращения, земной год | C2: Диаметр | D2: Расстояние от Солнца | E2: Масса, относительно Земли | F2: Количество спутников
D3: >=0,5 | E3: >=1 | F3: <=2
D4: >=0,5 | E4: <100 | F4: <=2
A6: Планета | B6: Период обращения, земной год | C6: Расстояние от Солнца | D6: Диаметр | E6: Масса, относительно Земли | F6: Количество спутников
A7: Меркурий | B7: 0.241 | C7: 0.38666667 | D7: 0.3828125 | E7: 0.053333333 | F7: 0
A8: Венера | B8: 0.615 | C8: 0.72 | D8: 0.9453125 | E8: 0.81 | F8: 0
A9: Земля | B9: 1 | C9: 1 | D9: 1 | E9: 1 | F9: 1
A10: Марс | B10: 1.881 | C10: 1.92 | D10: 0.53125 | E10: 0.10166667 | F10: 2
A11: Юпитер | B11: 11.86 | C11: 5.1866667 | D11: 11.140625 | E11: 317.83333 | F11: 16
A12: Сатурн | B12: 29.46 | C12: 9.5066667 | D12: 9.390625 | E12: 95.15 | F12: 17
A13: Уран | B13: 84.01 | C13: 19.126667 | D13: 3.828125 | E13: 14.54 | F13: 14
A14: Нептун | B14: 164.8 | C14: 29.973333 | D14: 3.921875 | E14: 17.233333 | F14: 2
A15: Плутон | B15: 247.7 | C15: 39.333333 | D15: 0.21875 | E15: 0.016666667 | F15: 1

Sheet 3.3.3 Автофильтр
A1: Автофильтр для трех планет имеющих самый большой диаметр
A2: Планета | B2: Период обращения, земной год | C2: Расстояние от Солнца, млн км | D2: Диаметр, тыс.км | E2: Масса, Тт | F2: Количество спутников | G2: Ранг
G3: <=3
A5: Планета | B5: Период обращения, земной год | C5: Расстояние от Солнца, млн км | D5: Диаметр, тыс.км | E5: Масса, Тт | F5: Количество спутников | G5: Ранг
A6: Меркурий | B6: 0.241 | C6: 0.38666667 | D6: 0.3828125 | E6: 0.053333333 | F6: 0 | G6: =RANK(D6, $D$6:$D$14, 0) -> 8
A7: Венера | B7: 0.615 | C7: 0.72 | D7: 0.9453125 | E7: 0.81 | F7: 0 | G7: =RANK(D7, $D$6:$D$14, 0) -> 6
A8: Земля | B8: 1 | C8: 1 | D8: 1 | E8: 1 | F8: 1 | G8: =RANK(D8, $D$6:$D$14, 0) -> 5
A9: Марс | B9: 1.881 | C9: 1.92 | D9: 0.53125 | E9: 0.10166667 | F9: 2 | G9: =RANK(D9, $D$6:$D$14, 0) -> 7
A10: Юпитер | B10: 11.86 | C10: 5.1866667 | D10: 11.140625 | E10: 317.83333 | F10: 16 | G10: =RANK(D10, $D$6:$D$14, 0) -> 1
A11: Сатурн | B11: 29.46 | C11: 9.5066667 | D11: 9.390625 | E11: 95.15 | F11: 17 | G11: =RANK(D11, $D$6:$D$14, 0) -> 2
A12: Уран | B12: 84.01 | C12: 19.126667 | D12: 3.828125 | E12: 14.54 | F12: 14 | G12: =RANK(D12, $D$6:$D$14, 0) -> 4
A13: Нептун | B13: 164.8 | C13: 29.973333 | D13: 3.921875 | E13: 17.233333 | F13: 2 | G13: =RANK(D13, $D$6:$D$14, 0) -> 3
A14: Плутон | B14: 247.7 | C14: 39.333333 | D14: 0.21875 | E14: 0.016666667 | F14: 1 | G14: =RANK(D14, $D$6:$D$14, 0) -> 9

Sheet 3.4 Расширенный фильтр
A1: Относительная таблица
A2: Планета | B2: Период обращения, земной год | C2: Расстояние от Солнца, млн км | D2: Диаметр, тыс.км | E2: Масса, Тт | F2: Количество спутников
A3: Меркурий | B3: 0.241 | C3: 0.38666667 | D3: 0.3828125 | E3: 0.053333333 | F3: 0
A4: Венера | B4: 0.615 | C4: 0.72 | D4: 0.9453125 | E4: 0.81 | F4: 0
A5: Земля | B5: 1 | C5: 1 | D5: 1 | E5: 1 | F5: 1
A6: Марс | B6: 1.881 | C6: 1.92 | D6: 0.53125 | E6: 0.10166667 | F6: 2
A7: Юпитер | B7: 11.86 | C7: 5.1866667 | D7: 11.140625 | E7: 317.83333 | F7: 16
A8: Сатурн | B8: 29.46 | C8: 9.5066667 | D8: 9.390625 | E8: 95.15 | F8: 17
A9: Уран | B9: 84.01 | C9: 19.126667 | D9: 3.828125 | E9: 14.54 | F9: 14
A10: Нептун | B10: 164.8 | C10: 29.973333 | D10: 3.921875 | E10: 17.233333 | F10: 2
A11: Плутон | B11: 247.7 | C11: 39.333333 | D11: 0.21875 | E11: 0.016666667 | F11: 1
A13: планеты с периодом обращения от 10 до 100 земных лет и количеством спутников не более 15
A14: Планета | B14: Период обращения, земной год | C14: Расстояние от Солнца, млн км | D14: Диаметр, тыс.км | E14: Масса, Тт | F14: Количество спутников
B15: >10 | F15: <=15
B16: <100 | F16: <=15
A18: Результат
A19: Планета | B19: Период обращения, земной год | C19: Расстояние от Солнца, млн км | D19: Диаметр, тыс.км | E19: Масса, Тт | F19: Количество спутников
A20: Меркурий | B20: 0.241 | C20: 0.38666667 | D20: 0.3828125 | E20: 0.053333333 | F20: 0
A21: Венера | B21: 0.615 | C21: 0.72 | D21: 0.9453125 | E21: 0.81 | F21: 0
A22: Земля | B22: 1 | C22: 1 | D22: 1 | E22: 1 | F22: 1
A23: Марс | B23: 1.881 | C23: 1.92 | D23: 0.53125 | E23: 0.10166667 | F23: 2
A24: Уран | B24: 84.01 | C24: 19.126667 | D24: 3.828125 | E24: 14.54 | F24: 14
A25: Нептун | B25: 164.8 | C25: 29.973333 | D25: 3.921875 | E25: 17.233333 | F25: 2
A26: Плутон | B26: 247.7 | C26: 39.333333 | D26: 0.21875 | E26: 0.016666667 | F26: 1
A28: планеты, у которых либо диаметр не менее 4-х земных, либо масса более 100 земных масс
A29: Планета | B29: Период обращения, земной год | C29: Расстояние от Солнца, млн км | D29: Диаметр, тыс.км | E29: Масса, Тт | F29: Количество спутников
D30: >=4
E31: >=100
A32: Результат
A33: Планета | B33: Период обращения, земной год | C33: Расстояние от Солнца, млн км | D33: Диаметр, тыс.км | E33: Масса, Тт | F33: Количество спутников
A34: Юпитер | B34: 11.86 | C34: 5.1866667 | D34: 11.140625 | E34: 317.83333 | F34: 16
A35: Сатурн | B35: 29.46 | C35: 9.5066667 | D35: 9.390625 | E35: 95.15 | F35: 17
A37: среди планет без спутников тех, которые находятся от Солнца на расстоянии менее половины земного, а среди планет с не менее чем 14-ю спутниками тех, которые находятся от Солнца не ближе чем 10 земных рассто
A38: Планета | B38: Период обращения, земной год | C38: Расстояние от Солнца, млн км | D38: Диаметр, тыс.км | E38: Масса, Тт | F38: Количество спутников
C39: >0,5 | F39: =0
C40: >=10 | F40: >=14
A42: Результат
A43: Планета | B43: Период обращения, земной год | C43: Расстояние от Солнца, млн км | D43: Диаметр, тыс.км | E43: Масса, Тт | F43: Количество спутников
A44: Венера | B44: 0.615 | C44: 0.72 | D44: 0.9453125 | E44: 0.81 | F44: 0
A45: Уран | B45: 84.01 | C45: 19.126667 | D45: 3.828125 | E45: 14.54 | F45: 14

Sheet 3.5 Создание сводной таблицы
A1: Исходная таблица
A2: Ф.И.О. | B2: Отдел | C2: Количество иждивенцев | D2: Всего начислено, руб. | E2: Процент удержания | F2: Всего удержано, руб. | G2: Сумма к выдаче, руб.
A3: Петухова К.И. | B3: 1 | C3: 1 | D3: 1260 | E3: {=_xlfn.IFS(C3>3,0,C3=3,5,C3=2,10,C3=1,12,C3=0,14)} -> 12 | F3: =(D3*E3)/100 -> 151.2 | G3: =D3-F3 -> 1108.8
A4: Безенчук П.Ф. | B4: 3 | C4: 2 | D4: 1100 | E4: {=_xlfn.IFS(C4>3,0,C4=3,5,C4=2,10,C4=1,12,C4=0,14)} -> 10 | F4: =(D4*E4)/100 -> 110 | G4: =D4-F4 -> 990
A5: Воробьянинов И.М. | B5: 2 | C5: 3 | D5: 800 | E5: {=_xlfn.IFS(C5>3,0,C5=3,5,C5=2,10,C5=1,12,C5=0,14)} -> 5 | F5: =(D5*E5)/100 -> 40 | G5: =D5-F5 -> 760
A6: Востриков Ф.О. | B6: 2 | C6: 2 | D6: 750 | E6: {=_xlfn.IFS(C6>3,0,C6=3,5,C6=2,10,C6=1,12,C6=0,14)} -> 10 | F6: =(D6*E6)/100 -> 75 | G6: =D6-F6 -> 675
A7: Коробейников В.А. | B7: 3 | C7: 1 | D7: 715 | E7: {=_xlfn.IFS(C7>3,0,C7=3,5,C7=2,10,C7=1,12,C7=0,14)} -> 12 | F7: =(D7*E7)/100 -> 85.8 | G7: =D7-F7 -> 629.2
A8: Грицацуева В.С. | B8: 1 | C8: 3 | D8: 630 | E8: {=_xlfn.IFS(C8>3,0,C8=3,5,C8=2,10,C8=1,12,C8=0,14)} -> 5 | F8: =(D8*E8)/100 -> 31.5 | G8: =D8-F8 -> 598.5
A9: Гаврилин З.С. | B9: 1 | C9: 4 | D9: 620 | E9: {=_xlfn.IFS(C9>3,0,C9=3,5,C9=2,10,C9=1,12,C9=0,14)} -> 0 | F9: =(D9*E9)/100 -> 0 | G9: =D9-F9 -> 620
A10: Треухов Т.И. | B10: 3 | C10: 1 | D10: 560 | E10: {=_xlfn.IFS(C10>3,0,C10=3,5,C10=2,10,C10=1,12,C10=0,14)} -> 12 | F10: =(D10*E10)/100 -> 67.2 | G10: =D10-F10 -> 492.8
A11: Изнуренков А.В. | B11: 1 | C11: 0 | D11: 420 | E11: {=_xlfn.IFS(C11>3,0,C11=3,5,C11=2,10,C11=1,12,C11=0,14)} -> 14 | F11: =(D11*E11)/100 -> 58.8 | G11: =D11-F11 -> 361.2
A12: Щукина Э.Е. | B12: 3 | C12: 1 | D12: 250 | E12: {=_xlfn.IFS(C12>3,0,C12=3,5,C12=2,10,C12=1,12,C12=0,14)} -> 12 | F12: =(D12*E12)/100 -> 30 | G12: =D12-F12 -> 220

Sheet Сводная таблица
A1: Количество иждивенцев | B1: 1
A2: Отдел | B2: 3
A4: Названия строк | B4: Количество по полю Отдел
A5: Коробейников В.А. | B5: 1
A6: Треухов Т.И. | B6: 1
A7: Щукина Э.Е. | B7: 1
A8: Общий итог | B8: 3

Sheet 3.6 Получение промежуточных ито
A1: Исходная таблица
A2: Ф.И.О. | B2: Отдел | C2: Количество иждивенцев | D2: Всего начислено, руб. | E2: Процент удержания | F2: Всего удержано, руб. | G2: Сумма к выдаче, руб.
A3: Изнуренков А.В. | B3: 1 | C3: 0 | D3: 420 | E3: {=_xlfn.IFS(C3>3,0,C3=3,5,C3=2,10,C3=1,12,C3=0,14)} -> 14 | F3: =(D3*E3)/100 -> 58.8 | G3: =D3-F3 -> 361.2
A4: Петухова К.И. | B4: 1 | C4: 1 | D4: 1260 | E4: {=_xlfn.IFS(C4>3,0,C4=3,5,C4=2,10,C4=1,12,C4=0,14)} -> 12 | F4: =(D4*E4)/100 -> 151.2 | G4: =D4-F4 -> 1108.8
A5: Грицацуева В.С. | B5: 1 | C5: 3 | D5: 630 | E5: {=_xlfn.IFS(C5>3,0,C5=3,5,C5=2,10,C5=1,12,C5=0,14)} -> 5 | F5: =(D5*E5)/100 -> 31.5 | G5: =D5-F5 -> 598.5
A6: Гаврилин З.С. | B6: 1 | C6: 4 | D6: 620 | E6: {=_xlfn.IFS(C6>3,0,C6=3,5,C6=2,10,C6=1,12,C6=0,14)} -> 0 | F6: =(D6*E6)/100 -> 0 | G6: =D6-F6 -> 620
B7: 1 Количество | C7: =SUBTOTAL(9,C3:C6) -> 8 | D7: =SUBTOTAL(9,D3:D6) -> 2930 | F7: =SUBTOTAL(9,F3:F6) -> 241.5 | G7: =SUBTOTAL(9,G3:G6) -> 2688.5
A8: Востриков Ф.О. | B8: 2 | C8: 2 | D8: 750 | E8: {=_xlfn.IFS(C8>3,0,C8=3,5,C8=2,10,C8=1,12,C8=0,14)} -> 10 | F8: =(D8*E8)/100 -> 75 | G8: =D8-F8 -> 675
A9: Воробьянинов И.М. | B9: 2 | C9: 3 | D9: 800 | E9: {=_xlfn.IFS(C9>3,0,C9=3,5,C9=2,10,C9=1,12,C9=0,14)} -> 5 | F9: =(D9*E9)/100 -> 40 | G9: =D9-F9 -> 760
B10: 2 Количество | C10: =SUBTOTAL(9,C8:C9) -> 5 | D10: =SUBTOTAL(9,D8:D9) -> 1550 | F10: =SUBTOTAL(9,F8:F9) -> 115 | G10: =SUBTOTAL(9,G8:G9) -> 1435
A11: Коробейников В.А. | B11: 3 | C11: 1 | D11: 715 | E11: {=_xlfn.IFS(C11>3,0,C11=3,5,C11=2,10,C11=1,12,C11=0,14)} -> 12 | F11: =(D11*E11)/100 -> 85.8 | G11: =D11-F11 -> 629.2
A12: Треухов Т.И. | B12: 3 | C12: 1 | D12: 560 | E12: {=_xlfn.IFS(C12>3,0,C12=3,5,C12=2,10,C12=1,12,C12=0,14)} -> 12 | F12: =(D12*E12)/100 -> 67.2 | G12: =D12-F12 -> 492.8
A13: Щукина Э.Е. | B13: 3 | C13: 1 | D13: 250 | E13: {=_xlfn.IFS(C13>3,0,C13=3,5,C13=2,10,C13=1,12,C13=0,14)} -> 12 | F13: =(D13*E13)/100 -> 30 | G13: =D13-F13 -> 220
A14: Безенчук П.Ф. | B14: 3 | C14: 2 | D14: 1100 | E14: {=_xlfn.IFS(C14>3,0,C14=3,5,C14=2,10,C14=1,12,C14=0,14)} -> 10 | F14: =(D14*E14)/100 -> 110 | G14: =D14-F14 -> 990
B15: 3 Количество | C15: =SUBTOTAL(9,C11:C14) -> 5 | D15: =SUBTOTAL(9,D11:D14) -> 2625 | F15: =SUBTOTAL(9,F11:F14) -> 293 | G15: =SUBTOTAL(9,G11:G14) -> 2332
B16: Общее количество | C16: =SUBTOTAL(9,C3:C14) -> 18 | D16: =SUBTOTAL(9,D3:D14) -> 7105 | F16: =SUBTOTAL(9,F3:F14) -> 649.5 | G16: =SUBTOTAL(9,G3:G14) -> 6455.5

Sheet 3.7.1 Формула связи. Январь
A1: Наименование продукции | B1: Исходные данные за январь
B2: Цена в USD | C2: Продано | D2: Выручка
A3: Телевизоры | B3: 350 | C3: 20 | D3: =C3*B3 -> 7000
A4: Ноутбуки | B4: 520 | C4: 35 | D4: =C4*B4 -> 18200
A5: Планшетные ПК | B5: 750 | C5: 65 | D5: =C5*B5 -> 48750
A6: Цифровые камеры | B6: 250 | C6: 30 | D6: =C6*B6 -> 7500
A7: Электронные книги | B7: 150 | C7: 15 | D7: =C7*B7 -> 2250
A8: Смартфоны | B8: 400 | C8: 27 | D8: =C8*B8 -> 10800
A9: Медиаплейеры | B9: 170 | C9: 11 | D9: =C9*B9 -> 1870
A10: Blu-ray плейеры | B10: 110 | C10: 14 | D10: =C10*B10 -> 1540
A11: Итого | D11: =SUM(D3:D10) -> 97910

Sheet 3.7.2 Формула связи. Февраль
A1: Наименование продукции | B1: Исходные данные за февраль
B2: Цена в USD | C2: Продано | D2: Выручка
A3: Телевизоры | B3: 350 | C3: 20 | D3: =C3*B3 -> 7000
A4: Ноутбуки | B4: 520 | C4: 35 | D4: =C4*B4 -> 18200
A5: Планшетные ПК | B5: 750 | C5: 65 | D5: =C5*B5 -> 48750
A6: Цифровые камеры | B6: 250 | C6: 30 | D6: =C6*B6 -> 7500
A7: Электронные книги | B7: 150 | C7: 15 | D7: =C7*B7 -> 2250
A8: Смартфоны | B8: 400 | C8: 27 | D8: =C8*B8 -> 10800
A9: Медиаплейеры | B9: 170 | C9: 11 | D9: =C9*B9 -> 1870
A10: Blu-ray плейеры | B10: 110 | C10: 14 | D10: =C10*B10 -> 1540
A11: Итого | D11: =SUM(D3:D10) -> 97910

Sheet 3.7.3 Формула связи. Март
A1: Наименование продукции | B1: Исходные данные за март
B2: Цена в USD | C2: Продано | D2: Выручка
A3: Телевизоры | B3: 350 | C3: 20 | D3: =C3*B3 -> 7000
A4: Ноутбуки | B4: 520 | C4: 35 | D4: =C4*B4 -> 18200
A5: Планшетные ПК | B5: 750 | C5: 65 | D5: =C5*B5 -> 48750
A6: Цифровые камеры | B6: 250 | C6: 30 | D6: =C6*B6 -> 7500
A7: Электронные книги | B7: 150 | C7: 15 | D7: =C7*B7 -> 2250
A8: Смартфоны | B8: 400 | C8: 27 | D8: =C8*B8 -> 10800
A9: Медиаплейеры | B9: 170 | C9: 11 | D9: =C9*B9 -> 1870
A10: Blu-ray плейеры | B10: 110 | C10: 14 | D10: =C10*B10 -> 1540
A11: Итого | D11: =SUM(D3:D10) -> 97910

Sheet 3.7.4 Квартрал. Способ 1
A1: Наименование продукции | B1: Исходные данные за квартал
B2: Цена в USD | C2: Продано | D2: Выручка
A3: Телевизоры | B3: 350 | C3: ='3.7.1 Формула связи. Январь'!C3+'3.7.2 Формула связи. Февраль'!C3+'3.7.3 Формула связи. Март'!C3 -> 60 | D3: ='3.7.1 Формула связи. Январь'!D3+'3.7.2 Формула связи. Февраль'!D3+'3.7.3 Формула связи. Март'!D3 -> 21000
A4: Ноутбуки | B4: 520 | C4: ='3.7.1 Формула связи. Январь'!C4+'3.7.2 Формула связи. Февраль'!C4+'3.7.3 Формула связи. Март'!C4 -> 105 | D4: ='3.7.1 Формула связи. Январь'!D4+'3.7.2 Формула связи. Февраль'!D4+'3.7.3 Формула связи. Март'!D4 -> 54600
A5: Планшетные ПК | B5: 750 | C5: ='3.7.1 Формула связи. Январь'!C5+'3.7.2 Формула связи. Февраль'!C5+'3.7.3 Формула связи. Март'!C5 -> 195 | D5: ='3.7.1 Формула связи. Январь'!D5+'3.7.2 Формула связи. Февраль'!D5+'3.7.3 Формула связи. Март'!D5 -> 146250
A6: Цифровые камеры | B6: 250 | C6: ='3.7.1 Формула связи. Январь'!C6+'3.7.2 Формула связи. Февраль'!C6+'3.7.3 Формула связи. Март'!C6 -> 90 | D6: ='3.7.1 Формула связи. Январь'!D6+'3.7.2 Формула связи. Февраль'!D6+'3.7.3 Формула связи. Март'!D6 -> 22500
A7: Электронные книги | B7: 150 | C7: ='3.7.1 Формула связи. Январь'!C7+'3.7.2 Формула связи. Февраль'!C7+'3.7.3 Формула связи. Март'!C7 -> 45 | D7: ='3.7.1 Формула связи. Январь'!D7+'3.7.2 Формула связи. Февраль'!D7+'3.7.3 Формула связи. Март'!D7 -> 6750
A8: Смартфоны | B8: 400 | C8: ='3.7.1 Формула связи. Январь'!C8+'3.7.2 Формула связи. Февраль'!C8+'3.7.3 Формула связи. Март'!C8 -> 81 | D8: ='3.7.1 Формула связи. Январь'!D8+'3.7.2 Формула связи. Февраль'!D8+'3.7.3 Формула связи. Март'!D8 -> 32400
A9: Медиаплейеры | B9: 170 | C9: ='3.7.1 Формула связи. Январь'!C9+'3.7.2 Формула связи. Февраль'!C9+'3.7.3 Формула связи. Март'!C9 -> 33 | D9: ='3.7.1 Формула связи. Январь'!D9+'3.7.2 Формула связи. Февраль'!D9+'3.7.3 Формула связи. Март'!D9 -> 5610
A10: Blu-ray плейеры | B10: 110 | C10: ='3.7.1 Формула связи. Январь'!C10+'3.7.2 Формула связи. Февраль'!C10+'3.7.3 Формула связи. Март'!C10 -> 42 | D10: ='3.7.1 Формула связи. Январь'!D10+'3.7.2 Формула связи. Февраль'!D10+'3.7.3 Формула связи. Март'!D10 -> 4620
C11: Итого | D11: =SUM(D3:D10) -> 293730

Sheet 3.7.5 Квартрал. Способ 2
A1: Наименование продукции | B1: Квартал
B2: Продано | C2: Выручка
B3: ='3.7.1 Формула связи. Январь'!$C$3 -> 20 | C3: ='3.7.1 Формула связи. Январь'!$D$3 -> 7000
B4: ='3.7.2 Формула связи. Февраль'!$C$3 -> 20 | C4: ='3.7.2 Формула связи. Февраль'!$D$3 -> 7000
B5: ='3.7.3 Формула связи. Март'!$C$3 -> 20 | C5: ='3.7.3 Формула связи. Март'!$D$3 -> 7000
A6: Телевизоры | B6: =SUM(B3:B5) -> 60 | C6: =SUM(C3:C5) -> 21000
B7: ='3.7.1 Формула связи. Январь'!$C$4 -> 35 | C7: ='3.7.1 Формула связи. Январь'!$D$4 -> 18200
B8: ='3.7.2 Формула связи. Февраль'!$C$4 -> 35 | C8: ='3.7.2 Формула связи. Февраль'!$D$4 -> 18200
B9: ='3.7.3 Формула связи. Март'!$C$4 -> 35 | C9: ='3.7.3 Формула связи. Март'!$D$4 -> 18200
A10: Ноутбуки | B10: =SUM(B7:B9) -> 105 | C10: =SUM(C7:C9) -> 54600
B11: ='3.7.1 Формула связи. Январь'!$C$5 -> 65 | C11: ='3.7.1 Формула связи. Январь'!$D$5 -> 48750
B12: ='3.7.2 Формула связи. Февраль'!$C$5 -> 65 | C12: ='3.7.2 Формула связи. Февраль'!$D$5 -> 48750
B13: ='3.7.3 Формула связи. Март'!$C$5 -> 65 | C13: ='3.7.3 Формула связи. Март'!$D$5 -> 48750
A14: Планшетные ПК | B14: =SUM(B11:B13) -> 195 | C14: =SUM(C11:C13) -> 146250
B15: ='3.7.1 Формула связи. Январь'!$C$6 -> 30 | C15: ='3.7.1 Формула связи. Январь'!$D$6 -> 7500
B16: ='3.7.2 Формула связи. Февраль'!$C$6 -> 30 | C16: ='3.7.2 Формула связи. Февраль'!$D$6 -> 7500
B17: ='3.7.3 Формула связи. Март'!$C$6 -> 30 | C17: ='3.7.3 Формула связи. Март'!$D$6 -> 7500
A18: Цифровые камеры | B18: =SUM(B15:B17) -> 90 | C18: =SUM(C15:C17) -> 22500
B19: ='3.7.1 Формула связи. Январь'!$C$7 -> 15 | C19: ='3.7.1 Формула связи. Январь'!$D$7 -> 2250
B20: ='3.7.2 Формула связи. Февраль'!$C$7 -> 15 | C20: ='3.7.2 Формула связи. Февраль'!$D$7 -> 2250
B21: ='3.7.3 Формула связи. Март'!$C$7 -> 15 | C21: ='3.7.3 Формула связи. Март'!$D$7 -> 2250
A22: Электронные книги | B22: =SUM(B19:B21) -> 45 | C22: =SUM(C19:C21) -> 6750
B23: ='3.7.1 Формула связи. Январь'!$C$8 -> 27 | C23: ='3.7.1 Формула связи. Январь'!$D$8 -> 10800
B24: ='3.7.2 Формула связи. Февраль'!$C$8 -> 27 | C24: ='3.7.2 Формула связи. Февраль'!$D$8 -> 10800
B25: ='3.7.3 Формула связи. Март'!$C$8 -> 27 | C25: ='3.7.3 Формула связи. Март'!$D$8 -> 10800
A26: Смартфоны | B26: =SUM(B23:B25) -> 81 | C26: =SUM(C23:C25) -> 32400
B27: ='3.7.1 Формула связи. Январь'!$C$9 -> 11 | C27: ='3.7.1 Формула связи. Январь'!$D$9 -> 1870
B28: ='3.7.2 Формула связи. Февраль'!$C$9 -> 11 | C28: ='3.7.2 Формула связи. Февраль'!$D$9 -> 1870
B29: ='3.7.3 Формула связи. Март'!$C$9 -> 11 | C29: ='3.7.3 Формула связи. Март'!$D$9 -> 1870
A30: Медиаплейеры | B30: =SUM(B27:B29) -> 33 | C30: =SUM(C27:C29) -> 5610
B31: ='3.7.1 Формула связи. Январь'!$C$10 -> 14 | C31: ='3.7.1 Формула связи. Январь'!$D$10 -> 1540
B32: ='3.7.2 Формула связи. Февраль'!$C$10 -> 14 | C32: ='3.7.2 Формула связи. Февраль'!$D$10 -> 1540
B33: ='3.7.3 Формула связи. Март'!$C$10 -> 14 | C33: ='3.7.3 Формула связи. Март'!$D$10 -> 1540
A34: Blu-ray плейеры | B34: =SUM(B31:B33) -> 42 | C34: =SUM(C31:C33) -> 4620
C35: ='3.7.1 Формула связи. Январь'!$D$11 -> 97910
C36: ='3.7.2 Формула связи. Февраль'!$D$11 -> 97910
C37: ='3.7.3 Формула связи. Март'!$D$11 -> 97910
A38: Итого | C38: =SUM(C35:C37) -> 293730

Sheet 3.8.1 Консолидация
A1: Период (1997 г.) | B1: Цены, тыс. руб. за тонну
B2: Нефть | C2: Бензин автомобильный | D2: Топливо дизельное | E2: Мазут топочный | F2: Газ естесственный | G2: Уголь
G3: энергетический | H3: для коксования
A5: январь | B5: 370 | C5: 933 | D5: 943 | E5: 443 | F5: 37.2 | G5: 144 | H5: 133
A6: февраль | B6: 373 | C6: 886 | D6: 944 | E6: 433 | F6: 39 | G6: 143 | H6: 130
A7: март | B7: 376 | C7: 907 | D7: 947 | E7: 434 | F7: 39 | G7: 146 | H7: 138
A8: средняя цена за квартал | B8: =AVERAGE(B5:B7) -> 373 | C8: =AVERAGE(C5:C7) -> 908.66667 | D8: =AVERAGE(D5:D7) -> 944.66667 | E8: =AVERAGE(E5:E7) -> 436.66667 | F8: =AVERAGE(F5:F7) -> 38.4 | G8: =AVERAGE(G5:G7) -> 144.33333 | H8: =AVERAGE(H5:H7) -> 133.66667
A9: Соотношение цен на виды энергоресурсов с ценой на нефть % | B9: =B8*100/$B$8 -> 100 | C9: =C8*100/$B$8 -> 243.61037 | D9: =D8*100/$B$8 -> 253.26184 | E9: =E8*100/$B$8 -> 117.06881 | F9: =F8*100/$B$8 -> 10.294906 | G9: =G8*100/$B$8 -> 38.695264 | H9: =H8*100/$B$8 -> 35.835567

Sheet 3.8.2 Консолидация
A1: Период (1997 г.) | B1: Цены, тыс. руб. за тонну
B2: Нефть | C2: Бензин автомобильный | D2: Топливо дизельное | E2: Мазут топочный | F2: Газ естесственный | G2: Уголь
G3: энергетический | H3: для коксования
A5: апрель | B5: 371 | C5: 932 | D5: 970 | E5: 440 | F5: 39 | G5: 141 | H5: 129
A6: май | B6: 372 | C6: 949 | D6: 980 | E6: 437 | F6: 39.3 | G6: 141 | H6: 136
A7: июнь | B7: 375 | C7: 968 | D7: 984 | E7: 436 | F7: 39.3 | G7: 141 | H7: 129
A8: средняя цена за квартал | B8: =AVERAGE(B5:B7) -> 372.66667 | C8: =AVERAGE(C5:C7) -> 949.66667 | D8: =AVERAGE(D5:D7) -> 978 | E8: =AVERAGE(E5:E7) -> 437.66667 | F8: =AVERAGE(F5:F7) -> 39.2 | G8: =AVERAGE(G5:G7) -> 141 | H8: =AVERAGE(H5:H7) -> 131.33333
A9: Соотношение цен на виды энергоресурсов с ценой на нефть % | B9: =B8*100/$B$8 -> 100 | C9: =C8*100/$B$8 -> 254.83005 | D9: =D8*100/$B$8 -> 262.43292 | E9: =E8*100/$B$8 -> 117.44186 | F9: =F8*100/$B$8 -> 10.518784 | G9: =G8*100/$B$8 -> 37.83542 | H9: =H8*100/$B$8 -> 35.241503

Sheet 3.8.3 Консолидация
A1: Период (1997 г.) | B1: Цены, тыс. руб. за тонну
B2: Нефть | C2: Бензин автомобильный | D2: Топливо дизельное | E2: Мазут топочный | F2: Газ естесственный | G2: Уголь
G3: энергетический | H3: для коксования
A5: июль | B5: 375 | C5: 968 | D5: 981 | E5: 441 | F5: 39.5 | G5: 139 | H5: 127
A6: август | B6: 375 | C6: 978 | D6: 981 | E6: 440 | F6: 39.6 | G6: 137 | H6: 128
A7: сентябрь | B7: 376 | C7: 1011 | D7: 1013 | E7: 440 | F7: 39.4 | G7: 138 | H7: 124
A8: средняя цена за квартал | B8: =AVERAGE(B5:B7) -> 375.33333 | C8: =AVERAGE(C5:C7) -> 985.66667 | D8: =AVERAGE(D5:D7) -> 991.66667 | E8: =AVERAGE(E5:E7) -> 440.33333 | F8: =AVERAGE(F5:F7) -> 39.5 | G8: =AVERAGE(G5:G7) -> 138 | H8: =AVERAGE(H5:H7) -> 126.33333
